import React, { Component, ReactNode } from 'react';
import { AlertTriangle, RefreshCcw } from 'lucide-react';
import { Button } from '@/components/ui/button';
import { Card, CardContent, CardDescription, CardHeader, CardTitle } from '@/components/ui/card';

interface Props {
  children: ReactNode;
  fallback?: ReactNode;
}

interface State {
  hasError: boolean;
  error: Error | null;
  errorInfo: React.ErrorInfo | null;
}

export class ErrorBoundary extends Component<Props, State> {
  constructor(props: Props) {
    super(props);
    this.state = { hasError: false, error: null, errorInfo: null };
  }

  static getDerivedStateFromError(error: Error): State {
    return { hasError: true, error, errorInfo: null };
  }

  componentDidCatch(error: Error, errorInfo: React.ErrorInfo) {
    console.error('Error caught by boundary:', error, errorInfo);
    this.setState({ error, errorInfo });
    
    // Log to error tracking service (could integrate Sentry, etc.)
    if (typeof window !== 'undefined') {
      localStorage.setItem('last_error', JSON.stringify({
        error: error.toString(),
        stack: error.stack,
        componentStack: errorInfo.componentStack,
        timestamp: new Date().toISOString(),
      }));
    }
  }

  handleReset = () => {
    this.setState({ hasError: false, error: null, errorInfo: null });
  };

  handleReload = () => {
    window.location.reload();
  };

  render() {
    if (this.state.hasError) {
      if (this.props.fallback) {
        return this.props.fallback;
      }

      return (
        <div className="min-h-screen bg-background flex items-center justify-center p-4">
          <Card className="max-w-2xl w-full">
            <CardHeader>
              <div className="flex items-center gap-3">
                <AlertTriangle className="h-8 w-8 text-destructive" />
                <div>
                  <CardTitle>Something went wrong</CardTitle>
                  <CardDescription>
                    The application encountered an unexpected error
                  </CardDescription>
                </div>
              </div>
            </CardHeader>
            <CardContent className="space-y-4">
              {this.state.error && (
                <div className="p-4 bg-destructive/10 border border-destructive/20 rounded-lg">
                  <div className="font-mono text-sm text-destructive">
                    {this.state.error.toString()}
                  </div>
                </div>
              )}

              <div className="flex gap-3">
                <Button onClick={this.handleReset} className="flex-1">
                  <RefreshCcw className="w-4 h-4 mr-2" />
                  Try Again
                </Button>
                <Button onClick={this.handleReload} variant="outline" className="flex-1">
                  Reload Page
                </Button>
              </div>

              {process.env.NODE_ENV === 'development' && this.state.errorInfo && (
                <details className="mt-4">
                  <summary className="cursor-pointer text-sm font-medium mb-2">
                    Technical Details (Development Only)
                  </summary>
                  <pre className="text-xs overflow-auto p-4 bg-muted rounded-lg max-h-64">
                    {this.state.errorInfo.componentStack}
                  </pre>
                </details>
              )}

              <div className="text-sm text-muted-foreground">
                If this problem persists, try clearing your browser cache or contact support.
              </div>
            </CardContent>
          </Card>
        </div>
      );
    }

    return this.props.children;
  }
}

// Hook for functional components
export const useErrorHandler = () => {
  const [error, setError] = React.useState<Error | null>(null);

  React.useEffect(() => {
    if (error) {
      throw error;
    }
  }, [error]);

  return setError;
};

// Utility for retry logic
export const withRetry = async <T,>(
  fn: () => Promise<T>,
  maxRetries: number = 3,
  delay: number = 1000
): Promise<T> => {
  let lastError: Error;
  
  for (let i = 0; i < maxRetries; i++) {
    try {
      return await fn();
    } catch (error) {
      lastError = error as Error;
      if (i < maxRetries - 1) {
        await new Promise(resolve => setTimeout(resolve, delay * (i + 1)));
      }
    }
  }
  
  throw lastError!;
};
